2015-12-22 14:03:51
Traceback (most recent call last):
  File "/Users/wbond/Library/Application Support/Sublime Text 3/Packages/SFTP/sftp/ftp_transport.py", line 206, in handle_ftp_error
  File "/Users/wbond/Library/Application Support/Sublime Text 3/Packages/SFTP/sftp/ftp_transport.py", line 190, in check_disconnect
  File "/Users/wbond/Library/Application Support/Sublime Text 3/Packages/SFTP/sftp/ftplib2.py", line 326, in getresp
SFTP.sftp.ftplib2.error_temp: 421 Idle timeout (600 seconds): closing control connection

During handling of the above exception, another exception occurred:

Traceback (most recent call last):
  File "/Users/wbond/Library/Application Support/Sublime Text 3/Packages/SFTP/sftp/commands.py", line 355, in run
  File "/Users/wbond/Library/Application Support/Sublime Text 3/Packages/SFTP/sftp/commands.py", line 510, in do_operation
  File "/Users/wbond/Library/Application Support/Sublime Text 3/Packages/SFTP/sftp/file_transfer.py", line 47, in handler
  File "/Users/wbond/Library/Application Support/Sublime Text 3/Packages/SFTP/sftp/ftp_transport.py", line 814, in put
  File "/Users/wbond/Library/Application Support/Sublime Text 3/Packages/SFTP/sftp/ftp_transport.py", line 805, in put
  File "/Users/wbond/Library/Application Support/Sublime Text 3/Packages/SFTP/sftp/file_transfer.py", line 394, in handle_put_dirs
  File "/Users/wbond/Library/Application Support/Sublime Text 3/Packages/SFTP/sftp/ftp_transport.py", line 516, in cd
  File "/Users/wbond/Library/Application Support/Sublime Text 3/Packages/SFTP/sftp/ftp_transport.py", line 511, in cd
  File "/Users/wbond/Library/Application Support/Sublime Text 3/Packages/SFTP/sftp/ftp_transport.py", line 361, in handle_ftp_error
SFTP.sftp.errors.DisconnectionError: Disconnected

During handling of the above exception, another exception occurred:

Traceback (most recent call last):
  File "/Users/wbond/Library/Application Support/Sublime Text 3/Packages/SFTP/sftp/ftp_transport.py", line 208, in handle_ftp_error
  File "/Users/wbond/Library/Application Support/Sublime Text 3/Packages/SFTP/sftp/ftp_transport.py", line 510, in do_cd
  File "/Users/wbond/Library/Application Support/Sublime Text 3/Packages/SFTP/sftp/ftplib2.py", line 707, in cwd
  File "/Users/wbond/Library/Application Support/Sublime Text 3/Packages/SFTP/sftp/ftplib2.py", line 364, in voidcmd
  File "/Users/wbond/Library/Application Support/Sublime Text 3/Packages/SFTP/sftp/ftplib2.py", line 333, in voidresp
  File "/Users/wbond/Library/Application Support/Sublime Text 3/Packages/SFTP/sftp/ftplib2.py", line 328, in getresp
SFTP.sftp.ftplib2.error_perm: 550 /Q:/_alpha/ft-shop.ru/catalog/view/theme/default/template/common: No such file or directory

During handling of the above exception, another exception occurred:

Traceback (most recent call last):
  File "/Users/wbond/Library/Application Support/Sublime Text 3/Packages/SFTP/sftp/ftp_transport.py", line 511, in cd
  File "/Users/wbond/Library/Application Support/Sublime Text 3/Packages/SFTP/sftp/ftp_transport.py", line 326, in handle_ftp_error
SFTP.sftp.errors.NotFoundError: File not found

During handling of the above exception, another exception occurred:

Traceback (most recent call last):
  File "/Users/wbond/Library/Application Support/Sublime Text 3/Packages/SFTP/sftp/file_transfer.py", line 394, in handle_put_dirs
  File "/Users/wbond/Library/Application Support/Sublime Text 3/Packages/SFTP/sftp/ftp_transport.py", line 516, in cd
SFTP.sftp.errors.NotFoundError: Folder not found

During handling of the above exception, another exception occurred:

Traceback (most recent call last):
  File "/Users/wbond/Library/Application Support/Sublime Text 3/Packages/SFTP/sftp/ftp_transport.py", line 208, in handle_ftp_error
  File "/Users/wbond/Library/Application Support/Sublime Text 3/Packages/SFTP/sftp/ftp_transport.py", line 510, in do_cd
  File "/Users/wbond/Library/Application Support/Sublime Text 3/Packages/SFTP/sftp/ftplib2.py", line 707, in cwd
  File "/Users/wbond/Library/Application Support/Sublime Text 3/Packages/SFTP/sftp/ftplib2.py", line 364, in voidcmd
  File "/Users/wbond/Library/Application Support/Sublime Text 3/Packages/SFTP/sftp/ftplib2.py", line 333, in voidresp
  File "/Users/wbond/Library/Application Support/Sublime Text 3/Packages/SFTP/sftp/ftplib2.py", line 328, in getresp
SFTP.sftp.ftplib2.error_perm: 550 /Q:/_alpha/ft-shop.ru/catalog/view/theme/default/template/common: No such file or directory

During handling of the above exception, another exception occurred:

Traceback (most recent call last):
  File "/Users/wbond/Library/Application Support/Sublime Text 3/Packages/SFTP/sftp/ftp_transport.py", line 511, in cd
  File "/Users/wbond/Library/Application Support/Sublime Text 3/Packages/SFTP/sftp/ftp_transport.py", line 326, in handle_ftp_error
SFTP.sftp.errors.NotFoundError: File not found

During handling of the above exception, another exception occurred:

Traceback (most recent call last):
  File "/Users/wbond/Library/Application Support/Sublime Text 3/Packages/SFTP/sftp/threads.py", line 16, in run_with_except_hook
  File "/Users/wbond/Library/Application Support/Sublime Text 3/Packages/SFTP/sftp/threads.py", line 119, in handler
  File "/Users/wbond/Library/Application Support/Sublime Text 3/Packages/SFTP/sftp/commands.py", line 371, in run
  File "/Users/wbond/Library/Application Support/Sublime Text 3/Packages/SFTP/sftp/commands.py", line 510, in do_operation
  File "/Users/wbond/Library/Application Support/Sublime Text 3/Packages/SFTP/sftp/file_transfer.py", line 47, in handler
  File "/Users/wbond/Library/Application Support/Sublime Text 3/Packages/SFTP/sftp/ftp_transport.py", line 814, in put
  File "/Users/wbond/Library/Application Support/Sublime Text 3/Packages/SFTP/sftp/ftp_transport.py", line 805, in put
  File "/Users/wbond/Library/Application Support/Sublime Text 3/Packages/SFTP/sftp/file_transfer.py", line 397, in handle_put_dirs
  File "/Users/wbond/Library/Application Support/Sublime Text 3/Packages/SFTP/sftp/ftp_transport.py", line 516, in cd
SFTP.sftp.errors.NotFoundError: Folder not found
